Workbook

Sheet Генерация
D1: 1 | E1: 1 | F1: 1 | G1: 1 | H1: 1 | I1: 2 | J1: 2 | K1: 2 | L1: 2 | M1: 2 | N1: 3 | O1: 3 | P1: 3 | Q1: 3 | R1: 3 | S1: 4 | T1: 4 | U1: 4 | V1: 4 | W1: 4 | X1: 5 | Y1: 5 | Z1: 5 | AA1: 5 | AB1: 5
D2: 1 | I2: 2 | N2: 3 | S2: 4 | X2: 5 | AD2: A | AE2: B | AF2: C | AG2: D
D3: 1 | E3: 2 | F3: 3 | G3: 4 | H3: 5 | I3: 1 | J3: 2 | K3: 3 | L3: 4 | M3: 5 | N3: 1 | O3: 2 | P3: 3 | Q3: 4 | R3: 5 | S3: 1 | T3: 2 | U3: 3 | V3: 4 | W3: 5 | X3: 1 | Y3: 2 | Z3: 3 | AA3: 4 | AB3: 5 | AD3: =QUOTIENT(LEN(AD5),2) -> 3 | AE3: =QUOTIENT(LEN(AE5),2) -> 3 | AF3: =AF5-6 -> 5 | AG3: =AG5-7 -> 17
A4: 1 | B4: 1 | C4: 1 | F4: =RANDBETWEEN($AD$3*F$1+$AE$3*F$3+$AF$3*$A4+$AG$3*$C4-1, $AD$3*F$1+$AE$3*F$3+$AF$3*$A4+$AG$3*$C4+1) -> 35 | AD4: Имя | AE4: Фамилия | AF4: Месяц | AG4: Вариант
A5: 1 | C5: 2 | Y5: =RANDBETWEEN($AD$3*Y$1+$AE$3*Y$3+$AF$3*$A5+$AG$3*$C5-1, $AD$3*Y$1+$AE$3*Y$3+$AF$3*$A5+$AG$3*$C5+1) -> 60 | AD5: Максим | AE5: Шарыгин | AF5: 11 | AG5: 24
A6: 1 | C6: 3 | S6: =RANDBETWEEN($AD$3*S$1+$AE$3*S$3+$AF$3*$A6+$AG$3*$C6-1, $AD$3*S$1+$AE$3*S$3+$AF$3*$A6+$AG$3*$C6+1) -> 71
A7: 1 | C7: 4 | M7: =RANDBETWEEN($AD$3*M$1+$AE$3*M$3+$AF$3*$A7+$AG$3*$C7-1, $AD$3*M$1+$AE$3*M$3+$AF$3*$A7+$AG$3*$C7+1) -> 94 | AD7: Проверка
A8: 1 | C8: 5 | Q8: =RANDBETWEEN($AD$3*Q$1+$AE$3*Q$3+$AF$3*$A8+$AG$3*$C8-1, $AD$3*Q$1+$AE$3*Q$3+$AF$3*$A8+$AG$3*$C8+1) -> 112 | AD8: x1 | AE8: x2 | AF8: x3 | AG8: x4
A9: 2 | B9: 2 | C9: 1 | R9: =RANDBETWEEN($AD$3*R$1+$AE$3*R$3+$AF$3*$A9+$AG$3*$C9-1, $AD$3*R$1+$AE$3*R$3+$AF$3*$A9+$AG$3*$C9+1) -> 52 | AD9: 1 | AE9: 3 | AF9: 1 | AG9: 1
A10: 2 | C10: 2 | G10: =RANDBETWEEN($AD$3*G$1+$AE$3*G$3+$AF$3*$A10+$AG$3*$C10-1, $AD$3*G$1+$AE$3*G$3+$AF$3*$A10+$AG$3*$C10+1) -> 58 | AD10: Результат
A11: 2 | C11: 3 | Z11: =RANDBETWEEN($AD$3*Z$1+$AE$3*Z$3+$AF$3*$A11+$AG$3*$C11-1, $AD$3*Z$1+$AE$3*Z$3+$AF$3*$A11+$AG$3*$C11+1) -> 85 | AD11: =AD3*AD9+AE3*AE9+AF3*AF9+AG3*AG9 -> 34
A12: 2 | C12: 4 | T12: =RANDBETWEEN($AD$3*T$1+$AE$3*T$3+$AF$3*$A12+$AG$3*$C12-1, $AD$3*T$1+$AE$3*T$3+$AF$3*$A12+$AG$3*$C12+1) -> 97
A13: 2 | C13: 5 | I13: =RANDBETWEEN($AD$3*I$1+$AE$3*I$3+$AF$3*$A13+$AG$3*$C13-1, $AD$3*I$1+$AE$3*I$3+$AF$3*$A13+$AG$3*$C13+1) -> 104
A14: 3 | B14: 3 | C14: 1 | J14: =RANDBETWEEN($AD$3*J$1+$AE$3*J$3+$AF$3*$A14+$AG$3*$C14-1, $AD$3*J$1+$AE$3*J$3+$AF$3*$A14+$AG$3*$C14+1) -> 45
A15: 3 | C15: 2 | N15: =RANDBETWEEN($AD$3*N$1+$AE$3*N$3+$AF$3*$A15+$AG$3*$C15-1, $AD$3*N$1+$AE$3*N$3+$AF$3*$A15+$AG$3*$C15+1) -> 60
A16: 3 | C16: 3 | H16: =RANDBETWEEN($AD$3*H$1+$AE$3*H$3+$AF$3*$A16+$AG$3*$C16-1, $AD$3*H$1+$AE$3*H$3+$AF$3*$A16+$AG$3*$C16+1) -> 85
A17: 3 | C17: 4 | AA17: =RANDBETWEEN($AD$3*AA$1+$AE$3*AA$3+$AF$3*$A17+$AG$3*$C17-1, $AD$3*AA$1+$AE$3*AA$3+$AF$3*$A17+$AG$3*$C17+1) -> 111
A18: 3 | C18: 5 | U18: =RANDBETWEEN($AD$3*U$1+$AE$3*U$3+$AF$3*$A18+$AG$3*$C18-1, $AD$3*U$1+$AE$3*U$3+$AF$3*$A18+$AG$3*$C18+1) -> 122
A19: 4 | B19: 4 | C19: 1 | X19: =RANDBETWEEN($AD$3*X$1+$AE$3*X$3+$AF$3*$A19+$AG$3*$C19-1, $AD$3*X$1+$AE$3*X$3+$AF$3*$A19+$AG$3*$C19+1) -> 56
A20: 4 | C20: 2 | W20: =RANDBETWEEN($AD$3*W$1+$AE$3*W$3+$AF$3*$A20+$AG$3*$C20-1, $AD$3*W$1+$AE$3*W$3+$AF$3*$A20+$AG$3*$C20+1) -> 80
A21: 4 | C21: 3 | L21: =RANDBETWEEN($AD$3*L$1+$AE$3*L$3+$AF$3*$A21+$AG$3*$C21-1, $AD$3*L$1+$AE$3*L$3+$AF$3*$A21+$AG$3*$C21+1) -> 90
A22: 4 | C22: 4 | P22: =RANDBETWEEN($AD$3*P$1+$AE$3*P$3+$AF$3*$A22+$AG$3*$C22-1, $AD$3*P$1+$AE$3*P$3+$AF$3*$A22+$AG$3*$C22+1) -> 105
A23: 4 | C23: 5 | E23: =RANDBETWEEN($AD$3*E$1+$AE$3*E$3+$AF$3*$A23+$AG$3*$C23-1, $AD$3*E$1+$AE$3*E$3+$AF$3*$A23+$AG$3*$C23+1) -> 113
A24: 5 | B24: 5 | C24: 1 | V24: =RANDBETWEEN($AD$3*V$1+$AE$3*V$3+$AF$3*$A24+$AG$3*$C24-1, $AD$3*V$1+$AE$3*V$3+$AF$3*$A24+$AG$3*$C24+1) -> 67
A25: 5 | C25: 2 | K25: =RANDBETWEEN($AD$3*K$1+$AE$3*K$3+$AF$3*$A25+$AG$3*$C25-1, $AD$3*K$1+$AE$3*K$3+$AF$3*$A25+$AG$3*$C25+1) -> 75
A26: 5 | C26: 3 | O26: =RANDBETWEEN($AD$3*O$1+$AE$3*O$3+$AF$3*$A26+$AG$3*$C26-1, $AD$3*O$1+$AE$3*O$3+$AF$3*$A26+$AG$3*$C26+1) -> 91
A27: 5 | C27: 4 | D27: =RANDBETWEEN($AD$3*D$1+$AE$3*D$3+$AF$3*$A27+$AG$3*$C27-1, $AD$3*D$1+$AE$3*D$3+$AF$3*$A27+$AG$3*$C27+1) -> 100
A28: 5 | C28: 5 | AB28: =RANDBETWEEN($AD$3*AB$1+$AE$3*AB$3+$AF$3*$A28+$AG$3*$C28-1, $AD$3*AB$1+$AE$3*AB$3+$AF$3*$A28+$AG$3*$C28+1) -> 139

Sheet Полученные значения
D2: 1 | I2: 2 | N2: 3 | S2: 4 | X2: 5
D3: 1 | E3: 2 | F3: 3 | G3: 4 | H3: 5 | I3: 1 | J3: 2 | K3: 3 | L3: 4 | M3: 5 | N3: 1 | O3: 2 | P3: 3 | Q3: 4 | R3: 5 | S3: 1 | T3: 2 | U3: 3 | V3: 4 | W3: 5 | X3: 1 | Y3: 2 | Z3: 3 | AA3: 4 | AB3: 5
B4: 1 | C4: 1 | F4: 35
C5: 2 | Y5: 59
C6: 3 | S6: 71
C7: 4 | M7: 95
C8: 5 | Q8: 112
B9: 2 | C9: 1 | R9: 51
C10: 2 | G10: 59
C11: 3 | Z11: 85
C12: 4 | T12: 96
C13: 5 | I13: 103
B14: 3 | C14: 1 | J14: 45
C15: 2 | N15: 61
C16: 3 | H16: 85
C17: 4 | AA17: 109
C18: 5 | U18: 122
B19: 4 | C19: 1 | X19: 54
C20: 2 | W20: 82
C21: 3 | L21: 89
C22: 4 | P22: 107
C23: 5 | E23: 114
B24: 5 | C24: 1 | V24: 65
C25: 2 | K25: 75
C26: 3 | O26: 91
C27: 4 | D27: 98
C28: 5 | AB28: 140

Sheet Лабораторная работа 2
B2: x2 | C2: x1 | H2: Среднее | J2: Параметр | K2: X1 | L2: Y | M2: X1^2 | N2: X1Y | O2: X2 | P2: Y | Q2: X2^2 | R2: X2Y | S2: X3 | T2: Y | U2: X3^2 | V2: X3Y | W2: X4 | X2: Y | Y2: X4^2 | Z2: X4Y
C3: 1 | D3: 2 | E3: 3 | F3: 4 | G3: 5 | J3: Значение | K3: 1 | L3: =C9 -> 78.2 | M3: =POWER(K3,2) -> 1 | N3: =K3*L3 -> 78.2 | O3: 1 | P3: =H4 -> 77.4 | Q3: =POWER(O3,2) -> 1 | R3: =O3*P3 -> 77.4 | S3: 1 | T3: =C18 -> 74.4 | U3: =POWER(S3,2) -> 1 | V3: =S3*T3 -> 74.4 | W3: 1 | X3: =H13 -> 50 | Y3: =POWER(W3,2) -> 1 | Z3: =W3*X3 -> 50
B4: 1 | C4: ='Полученные значения'!D27 -> 98 | D4: ='Полученные значения'!I13 -> 103 | E4: ='Полученные значения'!N15 -> 61 | F4: ='Полученные значения'!S6 -> 71 | G4: ='Полученные значения'!X19 -> 54 | H4: =AVERAGE(C4:G4) -> 77.4 | K4: 2 | L4: =D9 -> 81.4 | M4: =POWER(K4,2) -> 4 | N4: =K4*L4 -> 162.8 | O4: 2 | P4: =H5 -> 81 | Q4: =POWER(O4,2) -> 4 | R4: =O4*P4 -> 162 | S4: 2 | T4: =D18 -> 78.8 | U4: =POWER(S4,2) -> 4 | V4: =S4*T4 -> 157.6 | W4: 2 | X4: =H14 -> 67.2 | Y4: =POWER(W4,2) -> 4 | Z4: =W4*X4 -> 134.4
B5: 2 | C5: ='Полученные значения'!E23 -> 114 | D5: ='Полученные значения'!J14 -> 45 | E5: ='Полученные значения'!O26 -> 91 | F5: ='Полученные значения'!T12 -> 96 | G5: ='Полученные значения'!Y5 -> 59 | H5: =AVERAGE(C5:G5) -> 81 | K5: 3 | L5: =E9 -> 84.4 | M5: =POWER(K5,2) -> 9 | N5: =K5*L5 -> 253.2 | O5: 3 | P5: =H6 -> 84.8 | Q5: =POWER(O5,2) -> 9 | R5: =O5*P5 -> 254.4 | S5: 3 | T5: =E18 -> 84.4 | U5: =POWER(S5,2) -> 9 | V5: =S5*T5 -> 253.2 | W5: 3 | X5: =H15 -> 84.2 | Y5: =POWER(W5,2) -> 9 | Z5: =W5*X5 -> 252.6
B6: 3 | C6: ='Полученные значения'!F4 -> 35 | D6: ='Полученные значения'!K25 -> 75 | E6: ='Полученные значения'!P22 -> 107 | F6: ='Полученные значения'!U18 -> 122 | G6: ='Полученные значения'!Z11 -> 85 | H6: =AVERAGE(C6:G6) -> 84.8 | K6: 4 | L6: =F9 -> 87.2 | M6: =POWER(K6,2) -> 16 | N6: =K6*L6 -> 348.8 | O6: 4 | P6: =H7 -> 86.8 | Q6: =POWER(O6,2) -> 16 | R6: =O6*P6 -> 347.2 | S6: 4 | T6: =F18 -> 89.2 | U6: =POWER(S6,2) -> 16 | V6: =S6*T6 -> 356.8 | W6: 4 | X6: =H16 -> 101 | Y6: =POWER(W6,2) -> 16 | Z6: =W6*X6 -> 404
B7: 4 | C7: ='Полученные значения'!G10 -> 59 | D7: ='Полученные значения'!L21 -> 89 | E7: ='Полученные значения'!Q8 -> 112 | F7: ='Полученные значения'!V24 -> 65 | G7: ='Полученные значения'!AA17 -> 109 | H7: =AVERAGE(C7:G7) -> 86.8 | K7: 5 | L7: =G9 -> 89.4 | M7: =POWER(K7,2) -> 25 | N7: =K7*L7 -> 447 | O7: 5 | P7: =H8 -> 90.6 | Q7: =POWER(O7,2) -> 25 | R7: =O7*P7 -> 453 | S7: 5 | T7: =G18 -> 93.8 | U7: =POWER(S7,2) -> 25 | V7: =S7*T7 -> 469 | W7: 5 | X7: =H17 -> 118.2 | Y7: =POWER(W7,2) -> 25 | Z7: =W7*X7 -> 591
B8: 5 | C8: ='Полученные значения'!H16 -> 85 | D8: ='Полученные значения'!M7 -> 95 | E8: ='Полученные значения'!R9 -> 51 | F8: ='Полученные значения'!W20 -> 82 | G8: ='Полученные значения'!AB28 -> 140 | H8: =AVERAGE(C8:G8) -> 90.6 | J8: Сумма | K8: =SUM(K3:K7) -> 15 | L8: =SUM(L3:L7) -> 420.6 | M8: =SUM(M3:M7) -> 55 | N8: =SUM(N3:N7) -> 1290 | O8: =SUM(O3:O7) -> 15 | P8: =SUM(P3:P7) -> 420.6 | Q8: =SUM(Q3:Q7) -> 55 | R8: =SUM(R3:R7) -> 1294 | ... Z8: =SUM(Z3:Z7) -> 1432
B9: Среднее | C9: =AVERAGE(C4:C8) -> 78.2 | D9: =AVERAGE(D4:D8) -> 81.4 | E9: =AVERAGE(E4:E8) -> 84.4 | F9: =AVERAGE(F4:F8) -> 87.2 | G9: =AVERAGE(G4:G8) -> 89.4 | J9: Коэффициенты | K9: k | L9: =(5*N8-K8*L8)/(5*M8-K8*K8) -> 2.82 | M9: b | N9: =(L8-L9*K8)/5 -> 75.66 | O9: k | P9: =(5*R8-O8*P8)/(5*Q8-O8*O8) -> 3.22 | Q9: b | R9: =(P8-P9*O8)/5 -> 74.46 | S9: k | T9: =(5*V8-S8*T8)/(5*U8-S8*S8) -> 4.92 | U9: b | V9: =(T8-T9*S8)/5 -> 69.36 | W9: k | X9: =(5*Z8-W8*X8)/(5*Y8-W8*W8) -> 17.02 | Y9: b | Z9: =(X8-X9*W8)/5 -> 33.06
J10: Графики
B11: x4 | C11: x3 | H11: Среднее
C12: 1 | D12: 2 | E12: 3 | F12: 4 | G12: 5
B13: 1 | C13: ='Полученные значения'!F4 -> 35 | D13: ='Полученные значения'!R9 -> 51 | E13: ='Полученные значения'!J14 -> 45 | F13: ='Полученные значения'!X19 -> 54 | G13: ='Полученные значения'!V24 -> 65 | H13: =AVERAGE(C13:G13) -> 50
B14: 2 | C14: ='Полученные значения'!Y5 -> 59 | D14: ='Полученные значения'!G10 -> 59 | E14: ='Полученные значения'!N15 -> 61 | F14: ='Полученные значения'!W20 -> 82 | G14: ='Полученные значения'!K25 -> 75 | H14: =AVERAGE(C14:G14) -> 67.2
B15: 3 | C15: ='Полученные значения'!S6 -> 71 | D15: ='Полученные значения'!Z11 -> 85 | E15: ='Полученные значения'!H16 -> 85 | F15: ='Полученные значения'!L21 -> 89 | G15: ='Полученные значения'!O26 -> 91 | H15: =AVERAGE(C15:G15) -> 84.2
B16: 4 | C16: ='Полученные значения'!M7 -> 95 | D16: ='Полученные значения'!T12 -> 96 | E16: ='Полученные значения'!AA17 -> 109 | F16: ='Полученные значения'!P22 -> 107 | G16: ='Полученные значения'!D27 -> 98 | H16: =AVERAGE(C16:G16) -> 101
B17: 5 | C17: ='Полученные значения'!Q8 -> 112 | D17: ='Полученные значения'!I13 -> 103 | E17: ='Полученные значения'!U18 -> 122 | F17: ='Полученные значения'!E23 -> 114 | G17: ='Полученные значения'!AB28 -> 140 | H17: =AVERAGE(C17:G17) -> 118.2
B18: Среднее | C18: =AVERAGE(C13:C17) -> 74.4 | D18: =AVERAGE(D13:D17) -> 78.8 | E18: =AVERAGE(E13:E17) -> 84.4 | F18: =AVERAGE(F13:F17) -> 89.2 | G18: =AVERAGE(G13:G17) -> 93.8
B20: a1 | C20: a2 | D20: a3 | E20: a4 | F20: a0 | K20: x1 | L20: x2 | M20: x3 | N20: x4 | O20: Yэкс | P20: Y*рег | Q20: Delta* | R20: Yрег | S20: Delta | T20: (Yi-Yср)^2
B21: =L9 -> 2.82 | C21: =P9 -> 3.22 | D21: =T9 -> 4.92 | E21: =X9 -> 17.02 | F21: =AVERAGE(Q21:Q45) -> 0.18 | K21: 1 | L21: 3 | M21: 1 | N21: 1 | O21: ='Полученные значения'!F4 -> 35 | P21: =SUMPRODUCT($B$21:$E$21,K21:N21) -> 34.42 | Q21: =O21-P21 -> 0.58 | R21: =P21+$F$21 -> 34.6 | S21: =R21-O21 -> -0.4 | T21: =POWER(O21-$B$26, 2) -> 2412.7744
B22: Уравнение регрессии | K22: 1 | L22: 4 | M22: 2 | N22: 2 | O22: ='Полученные значения'!G10 -> 59 | P22: =SUMPRODUCT($B$21:$E$21,K22:N22) -> 59.58 | Q22: =O22-P22 -> -0.58 | R22: =P22+$F$21 -> 59.76 | S22: =R22-O22 -> 0.76 | T22: =POWER(O22-$B$26, 2) -> 631.0144
B23: Y = 2,82X1 + 3,22X2 + 4,92X3 + 17,02X4 + 0,18 | K23: 1 | L23: 5 | M23: 3 | N23: 3 | O23: ='Полученные значения'!H16 -> 85 | P23: =SUMPRODUCT($B$21:$E$21,K23:N23) -> 84.74 | Q23: =O23-P23 -> 0.26 | R23: =P23+$F$21 -> 84.92 | S23: =R23-O23 -> -0.08 | T23: =POWER(O23-$B$26, 2) -> 0.7744
K24: 1 | L24: 2 | M24: 4 | N24: 5 | O24: ='Полученные значения'!E23 -> 114 | P24: =SUMPRODUCT($B$21:$E$21,K24:N24) -> 114.04 | Q24: =O24-P24 -> -0.04 | R24: =P24+$F$21 -> 114.22 | S24: =R24-O24 -> 0.22 | T24: =POWER(O24-$B$26, 2) -> 892.8144
B25: Yср | C25: F | D25: Fт | E25: k1 | F25: k2 | K25: 1 | L25: 1 | M25: 5 | N25: 4 | O25: ='Полученные значения'!D27 -> 98 | P25: =SUMPRODUCT($B$21:$E$21,K25:N25) -> 98.72 | Q25: =O25-P25 -> -0.72 | R25: =P25+$F$21 -> 98.9 | S25: =R25-O25 -> 0.9 | T25: =POWER(O25-$B$26, 2) -> 192.6544
B26: =AVERAGE(O21:O45) -> 84.12 | C26: =FTEST(O21:O45,T21:T45) -> 1.4006302e-29 | D26: 1.98 | E26: 24 | F26: 24 | K26: 2 | L26: 5 | M26: 1 | N26: 4 | O26: ='Полученные значения'!M7 -> 95 | P26: =SUMPRODUCT($B$21:$E$21,K26:N26) -> 94.74 | Q26: =O26-P26 -> 0.26 | R26: =P26+$F$21 -> 94.92 | S26: =R26-O26 -> -0.08 | T26: =POWER(O26-$B$26, 2) -> 118.3744
K27: 2 | L27: 1 | M27: 2 | N27: 5 | O27: ='Полученные значения'!I13 -> 103 | P27: =SUMPRODUCT($B$21:$E$21,K27:N27) -> 103.8 | Q27: =O27-P27 -> -0.8 | R27: =P27+$F$21 -> 103.98 | S27: =R27-O27 -> 0.98 | T27: =POWER(O27-$B$26, 2) -> 356.4544
B28: F < Fт => модель адекватна | K28: 2 | L28: 2 | M28: 3 | N28: 1 | O28: ='Полученные значения'!J14 -> 45 | P28: =SUMPRODUCT($B$21:$E$21,K28:N28) -> 43.86 | Q28: =O28-P28 -> 1.14 | R28: =P28+$F$21 -> 44.04 | S28: =R28-O28 -> -0.96 | T28: =POWER(O28-$B$26, 2) -> 1530.3744
K29: 2 | L29: 4 | M29: 4 | N29: 3 | O29: ='Полученные значения'!L21 -> 89 | P29: =SUMPRODUCT($B$21:$E$21,K29:N29) -> 89.26 | Q29: =O29-P29 -> -0.26 | R29: =P29+$F$21 -> 89.44 | S29: =R29-O29 -> 0.44 | T29: =POWER(O29-$B$26, 2) -> 23.8144
K30: 2 | L30: 3 | M30: 5 | N30: 2 | O30: ='Полученные значения'!K25 -> 75 | P30: =SUMPRODUCT($B$21:$E$21,K30:N30) -> 73.94 | Q30: =O30-P30 -> 1.06 | R30: =P30+$F$21 -> 74.12 | S30: =R30-O30 -> -0.88 | T30: =POWER(O30-$B$26, 2) -> 83.1744
K31: 3 | L31: 4 | M31: 1 | N31: 5 | O31: ='Полученные значения'!Q8 -> 112 | P31: =SUMPRODUCT($B$21:$E$21,K31:N31) -> 111.36 | Q31: =O31-P31 -> 0.64 | R31: =P31+$F$21 -> 111.54 | S31: =R31-O31 -> -0.46 | T31: =POWER(O31-$B$26, 2) -> 777.2944
K32: 3 | L32: 5 | M32: 2 | N32: 1 | O32: ='Полученные значения'!R9 -> 51 | P32: =SUMPRODUCT($B$21:$E$21,K32:N32) -> 51.42 | Q32: =O32-P32 -> -0.42 | R32: =P32+$F$21 -> 51.6 | S32: =R32-O32 -> 0.6 | T32: =POWER(O32-$B$26, 2) -> 1096.9344
K33: 3 | L33: 1 | M33: 3 | N33: 2 | O33: ='Полученные значения'!N15 -> 61 | P33: =SUMPRODUCT($B$21:$E$21,K33:N33) -> 60.48 | Q33: =O33-P33 -> 0.52 | R33: =P33+$F$21 -> 60.66 | S33: =R33-O33 -> -0.34 | T33: =POWER(O33-$B$26, 2) -> 534.5344
K34: 3 | L34: 3 | M34: 4 | N34: 4 | O34: ='Полученные значения'!P22 -> 107 | P34: =SUMPRODUCT($B$21:$E$21,K34:N34) -> 105.88 | Q34: =O34-P34 -> 1.12 | R34: =P34+$F$21 -> 106.06 | S34: =R34-O34 -> -0.94 | T34: =POWER(O34-$B$26, 2) -> 523.4944
K35: 3 | L35: 2 | M35: 5 | N35: 3 | O35: ='Полученные значения'!O26 -> 91 | P35: =SUMPRODUCT($B$21:$E$21,K35:N35) -> 90.56 | Q35: =O35-P35 -> 0.44 | R35: =P35+$F$21 -> 90.74 | S35: =R35-O35 -> -0.26 | T35: =POWER(O35-$B$26, 2) -> 47.3344
K36: 4 | L36: 1 | M36: 1 | N36: 3 | O36: ='Полученные значения'!S6 -> 71 | P36: =SUMPRODUCT($B$21:$E$21,K36:N36) -> 70.48 | Q36: =O36-P36 -> 0.52 | R36: =P36+$F$21 -> 70.66 | S36: =R36-O36 -> -0.34 | T36: =POWER(O36-$B$26, 2) -> 172.1344
K37: 4 | L37: 2 | M37: 2 | N37: 4 | O37: ='Полученные значения'!T12 -> 96 | P37: =SUMPRODUCT($B$21:$E$21,K37:N37) -> 95.64 | Q37: =O37-P37 -> 0.36 | R37: =P37+$F$21 -> 95.82 | S37: =R37-O37 -> -0.18 | T37: =POWER(O37-$B$26, 2) -> 141.1344
K38: 4 | L38: 3 | M38: 3 | N38: 5 | O38: ='Полученные значения'!U18 -> 122 | P38: =SUMPRODUCT($B$21:$E$21,K38:N38) -> 120.8 | Q38: =O38-P38 -> 1.2 | R38: =P38+$F$21 -> 120.98 | S38: =R38-O38 -> -1.02 | T38: =POWER(O38-$B$26, 2) -> 1434.8944
K39: 4 | L39: 5 | M39: 4 | N39: 2 | O39: ='Полученные значения'!W20 -> 82 | P39: =SUMPRODUCT($B$21:$E$21,K39:N39) -> 81.1 | Q39: =O39-P39 -> 0.9 | R39: =P39+$F$21 -> 81.28 | S39: =R39-O39 -> -0.72 | T39: =POWER(O39-$B$26, 2) -> 4.4944
K40: 4 | L40: 4 | M40: 5 | N40: 1 | O40: ='Полученные значения'!V24 -> 65 | P40: =SUMPRODUCT($B$21:$E$21,K40:N40) -> 65.78 | Q40: =O40-P40 -> -0.78 | R40: =P40+$F$21 -> 65.96 | S40: =R40-O40 -> 0.96 | T40: =POWER(O40-$B$26, 2) -> 365.5744
K41: 5 | L41: 2 | M41: 1 | N41: 2 | O41: ='Полученные значения'!Y5 -> 59 | P41: =SUMPRODUCT($B$21:$E$21,K41:N41) -> 59.5 | Q41: =O41-P41 -> -0.5 | R41: =P41+$F$21 -> 59.68 | S41: =R41-O41 -> 0.68 | T41: =POWER(O41-$B$26, 2) -> 631.0144
K42: 5 | L42: 3 | M42: 2 | N42: 3 | O42: ='Полученные значения'!Z11 -> 85 | P42: =SUMPRODUCT($B$21:$E$21,K42:N42) -> 84.66 | Q42: =O42-P42 -> 0.34 | R42: =P42+$F$21 -> 84.84 | S42: =R42-O42 -> -0.16 | T42: =POWER(O42-$B$26, 2) -> 0.7744
...

Sheet Лабораторная работа 3
B2: x1 | C2: x2 | D2: x3 | E2: x4 | F2: Yрег | H2: k | I2: R | J2: r | L2: Номер шага | M2: x1 | N2: x2 | O2: x3 | P2: x4 | Q2: Y | R2: Ymax - Ymin | U2: x1 | V2: x2 | W2: x3 | X2: x4 | Y2: Ymax
B3: 1 | C3: 3 | D3: 1 | E3: 1 | F3: ='Лабораторная работа 2'!P21+'Лабораторная работа 2'!$F$21 -> 34.6 | H3: 1 | I3: 0.5 | J3: 0.5 | L3: 0 | M3: =-J3 -> -0.5 | N3: =-J4 -> -0.28867513 | O3: =-J5 -> -0.20412415 | P3: =-J6 -> -0.15811388 | Q3: =SUMPRODUCT($B$30:$E$30,M3:P3)+$F$30 -> -5.854923 | R3: =MAX(Q3:Q7)-MIN(Q3:Q7) -> 16.799392 | T3: Оптимальные значения | U3: {=INDIRECT("M" & MAX(IF(Q:Q=Y3, ROW(Q:Q), )))} -> 4.7725691 | V3: {=INDIRECT("N" & MAX(IF(Q:Q=Y3, ROW(Q:Q), )))} -> 4.8711111 | W3: {=INDIRECT("O" & MAX(IF(Q:Q=Y3, ROW(Q:Q), )))} -> 4.9261658 | X3: {=INDIRECT("P" & MAX(IF(Q:Q=Y3, ROW(Q:Q), )))} -> 5 | Y3: =MAX(INDIRECT("Q" & COUNTA(P:P)-5):INDIRECT("Q" & COUNTA(P:P)-1)) -> 138.66036
B4: 1 | C4: 4 | D4: 2 | E4: 2 | F4: ='Лабораторная работа 2'!P22+'Лабораторная работа 2'!$F$21 -> 59.76 | H4: 2 | I4: 0.57735 | J4: 0.28867513 | M4: =I3 -> 0.5 | N4: =-J4 -> -0.28867513 | O4: =-J5 -> -0.20412415 | P4: =-J6 -> -0.15811388 | Q4: =SUMPRODUCT($B$30:$E$30,M4:P4)+$F$30 -> -3.034923
B5: 1 | C5: 5 | D5: 3 | E5: 3 | F5: ='Лабораторная работа 2'!P23+'Лабораторная работа 2'!$F$21 -> 84.92 | H5: 3 | I5: 0.61237 | J5: 0.20412415 | M5: 0 | N5: =I4 -> 0.57735 | O5: =-J5 -> -0.20412415 | P5: =-J6 -> -0.15811388 | Q5: =SUMPRODUCT($B$30:$E$30,M5:P5)+$F$30 -> -1.6563221
B6: 1 | C6: 2 | D6: 4 | E6: 5 | F6: ='Лабораторная работа 2'!P24+'Лабораторная работа 2'!$F$21 -> 114.22 | H6: 4 | I6: 0.63246 | J6: 0.15811388 | M6: 0 | N6: 0 | O6: =I5 -> 0.61237 | P6: =-J6 -> -0.15811388 | Q6: =SUMPRODUCT($B$30:$E$30,M6:P6)+$F$30 -> 0.50176216
B7: 1 | C7: 1 | D7: 5 | E7: 4 | F7: ='Лабораторная работа 2'!P25+'Лабораторная работа 2'!$F$21 -> 98.9 | M7: 0 | N7: 0 | O7: 0 | P7: =I6 -> 0.63246 | Q7: =SUMPRODUCT($B$30:$E$30,M7:P7)+$F$30 -> 10.944469
B8: 2 | C8: 5 | D8: 1 | E8: 4 | F8: ='Лабораторная работа 2'!P26+'Лабораторная работа 2'!$F$21 -> 94.92 | L8: 1 | M8: =M3+3 -> 2.5 | N8: =N3+3 -> 2.7113249 | O8: =O3+3 -> 2.7958758 | P8: =P3+3 -> 2.8418861 | Q8: =SUMPRODUCT($B$30:$E$30,M8:P8)+$F$30 -> 78.085077 | R8: =MAX(Q8:Q12)-MIN(Q8:Q12) -> 16.799392
B9: 2 | C9: 1 | D9: 2 | E9: 5 | F9: ='Лабораторная работа 2'!P27+'Лабораторная работа 2'!$F$21 -> 103.98 | M9: =M4+3 -> 3.5 | N9: =N4+3 -> 2.7113249 | O9: =O4+3 -> 2.7958758 | P9: =P4+3 -> 2.8418861 | Q9: =SUMPRODUCT($B$30:$E$30,M9:P9)+$F$30 -> 80.905077
B10: 2 | C10: 2 | D10: 3 | E10: 1 | F10: ='Лабораторная работа 2'!P28+'Лабораторная работа 2'!$F$21 -> 44.04 | M10: =M5+3 -> 3 | N10: =N5+3 -> 3.57735 | O10: =O5+3 -> 2.7958758 | P10: =P5+3 -> 2.8418861 | Q10: =SUMPRODUCT($B$30:$E$30,M10:P10)+$F$30 -> 82.283678
B11: 2 | C11: 4 | D11: 4 | E11: 3 | F11: ='Лабораторная работа 2'!P29+'Лабораторная работа 2'!$F$21 -> 89.44 | M11: =M6+3 -> 3 | N11: =N6+3 -> 3 | O11: =O6+3 -> 3.61237 | P11: =P6+3 -> 2.8418861 | Q11: =SUMPRODUCT($B$30:$E$30,M11:P11)+$F$30 -> 84.441762
B12: 2 | C12: 3 | D12: 5 | E12: 2 | F12: ='Лабораторная работа 2'!P30+'Лабораторная работа 2'!$F$21 -> 74.12 | M12: =M7+3 -> 3 | N12: =N7+3 -> 3 | O12: =O7+3 -> 3 | P12: =P7+3 -> 3.63246 | Q12: =SUMPRODUCT($B$30:$E$30,M12:P12)+$F$30 -> 94.884469
B13: 3 | C13: 4 | D13: 1 | E13: 5 | F13: ='Лабораторная работа 2'!P31+'Лабораторная работа 2'!$F$21 -> 111.54 | L13: Новая вершина | M13: =IF($Q8=MIN($Q8:$Q12),-M8,M8)+IF($Q9=MIN($Q8:$Q12),-M9,M9)+IF($Q10=MIN($Q8:$Q12),-M10,M10)+IF($Q11=MIN($Q8:$Q12), -M11,M11)+IF($Q12=MIN($Q8:$Q12),-M12,M12) -> 10 | N13: =IF($Q8=MIN($Q8:$Q12),-N8,N8)+IF($Q9=MIN($Q8:$Q12),-N9,N9)+IF($Q10=MIN($Q8:$Q12),-N10,N10)+IF($Q11=MIN($Q8:$Q12), -N11,N11)+IF($Q12=MIN($Q8:$Q12),-N12,N12) -> 9.57735 | O13: =IF($Q8=MIN($Q8:$Q12),-O8,O8)+IF($Q9=MIN($Q8:$Q12),-O9,O9)+IF($Q10=MIN($Q8:$Q12),-O10,O10)+IF($Q11=MIN($Q8:$Q12), -O11,O11)+IF($Q12=MIN($Q8:$Q12),-O12,O12) -> 9.4082459 | P13: =IF($Q8=MIN($Q8:$Q12),-P8,P8)+IF($Q9=MIN($Q8:$Q12),-P9,P9)+IF($Q10=MIN($Q8:$Q12),-P10,P10)+IF($Q11=MIN($Q8:$Q12), -P11,P11)+IF($Q12=MIN($Q8:$Q12),-P12,P12) -> 9.3162322 | Q13: =MAX(M13:P13) -> 10 | R13: =Q13/5 -> 2
B14: 3 | C14: 5 | D14: 2 | E14: 1 | F14: ='Лабораторная работа 2'!P32+'Лабораторная работа 2'!$F$21 -> 51.6 | L14: Новая пересчитанная вершина | M14: =M13/$R13 -> 5 | N14: =N13/$R13 -> 4.788675 | O14: =O13/$R13 -> 4.7041229 | P14: =P13/$R13 -> 4.6581161
B15: 3 | C15: 1 | D15: 3 | E15: 2 | F15: ='Лабораторная работа 2'!P33+'Лабораторная работа 2'!$F$21 -> 60.66 | L15: 2 | M15: =IF($Q8=MIN($Q8:$Q12),M14,M8) -> 5 | N15: =IF($Q8=MIN($Q8:$Q12),N14,N8) -> 4.788675 | O15: =IF($Q8=MIN($Q8:$Q12),O14,O8) -> 4.7041229 | P15: =IF($Q8=MIN($Q8:$Q12),P14,P8) -> 4.6581161 | Q15: =SUMPRODUCT($B$30:$E$30,M15:P15)+$F$30 -> 132.12495 | R15: =MAX(Q15:Q19)-MIN(Q15:Q19) -> 51.219878
B16: 3 | C16: 3 | D16: 4 | E16: 4 | F16: ='Лабораторная работа 2'!P34+'Лабораторная работа 2'!$F$21 -> 106.06 | M16: =IF($Q9=MIN($Q8:$Q12),M14,M9) -> 3.5 | N16: =IF($Q9=MIN($Q8:$Q12),N14,N9) -> 2.7113249 | O16: =IF($Q9=MIN($Q8:$Q12),O14,O9) -> 2.7958758 | P16: =IF($Q9=MIN($Q8:$Q12),P14,P9) -> 2.8418861 | Q16: =SUMPRODUCT($B$30:$E$30,M16:P16)+$F$30 -> 80.905077
B17: 3 | C17: 2 | D17: 5 | E17: 3 | F17: ='Лабораторная работа 2'!P35+'Лабораторная работа 2'!$F$21 -> 90.74 | M17: =IF($Q10=MIN($Q8:$Q12),M14,M10) -> 3 | N17: =IF($Q10=MIN($Q8:$Q12),N14,N10) -> 3.57735 | O17: =IF($Q10=MIN($Q8:$Q12),O14,O10) -> 2.7958758 | P17: =IF($Q10=MIN($Q8:$Q12),P14,P10) -> 2.8418861 | Q17: =SUMPRODUCT($B$30:$E$30,M17:P17)+$F$30 -> 82.283678
B18: 4 | C18: 1 | D18: 1 | E18: 3 | F18: ='Лабораторная работа 2'!P36+'Лабораторная работа 2'!$F$21 -> 70.66 | M18: =IF($Q11=MIN($Q8:$Q12),M14,M11) -> 3 | N18: =IF($Q11=MIN($Q8:$Q12),N14,N11) -> 3 | O18: =IF($Q11=MIN($Q8:$Q12),O14,O11) -> 3.61237 | P18: =IF($Q11=MIN($Q8:$Q12),P14,P11) -> 2.8418861 | Q18: =SUMPRODUCT($B$30:$E$30,M18:P18)+$F$30 -> 84.441762
B19: 4 | C19: 2 | D19: 2 | E19: 4 | F19: ='Лабораторная работа 2'!P37+'Лабораторная работа 2'!$F$21 -> 95.82 | M19: =IF($Q12=MIN($Q8:$Q12),M14,M12) -> 3 | N19: =IF($Q12=MIN($Q8:$Q12),N14,N12) -> 3 | O19: =IF($Q12=MIN($Q8:$Q12),O14,O12) -> 3 | P19: =IF($Q12=MIN($Q8:$Q12),P14,P12) -> 3.63246 | Q19: =SUMPRODUCT($B$30:$E$30,M19:P19)+$F$30 -> 94.884469
B20: 4 | C20: 3 | D20: 3 | E20: 5 | F20: ='Лабораторная работа 2'!P38+'Лабораторная работа 2'!$F$21 -> 120.98 | L20: Новая вершина | M20: =IF($Q15=MIN($Q15:$Q19),-M15,M15)+IF($Q16=MIN($Q15:$Q19),-M16,M16)+IF($Q17=MIN($Q15:$Q19),-M17,M17)+IF($Q18=MIN($Q15:$Q19), -M18,M18)+IF($Q19=MIN($Q15:$Q19),-M19,M19) -> 10.5 | N20: =IF($Q15=MIN($Q15:$Q19),-N15,N15)+IF($Q16=MIN($Q15:$Q19),-N16,N16)+IF($Q17=MIN($Q15:$Q19),-N17,N17)+IF($Q18=MIN($Q15:$Q19), -N18,N18)+IF($Q19=MIN($Q15:$Q19),-N19,N19) -> 11.6547 | O20: =IF($Q15=MIN($Q15:$Q19),-O15,O15)+IF($Q16=MIN($Q15:$Q19),-O16,O16)+IF($Q17=MIN($Q15:$Q19),-O17,O17)+IF($Q18=MIN($Q15:$Q19), -O18,O18)+IF($Q19=MIN($Q15:$Q19),-O19,O19) -> 11.316493 | P20: =IF($Q15=MIN($Q15:$Q19),-P15,P15)+IF($Q16=MIN($Q15:$Q19),-P16,P16)+IF($Q17=MIN($Q15:$Q19),-P17,P17)+IF($Q18=MIN($Q15:$Q19), -P18,P18)+IF($Q19=MIN($Q15:$Q19),-P19,P19) -> 11.132462 | Q20: =MAX(M20:P20) -> 11.6547 | R20: =Q20/5 -> 2.33094
B21: 4 | C21: 5 | D21: 4 | E21: 2 | F21: ='Лабораторная работа 2'!P39+'Лабораторная работа 2'!$F$21 -> 81.28 | L21: Новая пересчитанная вершина | M21: =M20/$R20 -> 4.5046204 | N21: =N20/$R20 -> 5 | O21: =O20/$R20 -> 4.8549052 | P21: =P20/$R20 -> 4.775954
B22: 4 | C22: 4 | D22: 5 | E22: 1 | F22: ='Лабораторная работа 2'!P40+'Лабораторная работа 2'!$F$21 -> 65.96 | L22: 3 | M22: =IF($Q15=MIN($Q15:$Q19),M21,M15) -> 5 | N22: =IF($Q15=MIN($Q15:$Q19),N21,N15) -> 4.788675 | O22: =IF($Q15=MIN($Q15:$Q19),O21,O15) -> 4.7041229 | P22: =IF($Q15=MIN($Q15:$Q19),P21,P15) -> 4.6581161 | Q22: =SUMPRODUCT($B$30:$E$30,M22:P22)+$F$30 -> 132.12495 | R22: =MAX(Q22:Q26)-MIN(Q22:Q26) -> 51.872222
B23: 5 | C23: 2 | D23: 1 | E23: 2 | F23: ='Лабораторная работа 2'!P41+'Лабораторная работа 2'!$F$21 -> 59.68 | M23: =IF($Q16=MIN($Q15:$Q19),M21,M16) -> 4.5046204 | N23: =IF($Q16=MIN($Q15:$Q19),N21,N16) -> 5 | O23: =IF($Q16=MIN($Q15:$Q19),O21,O16) -> 4.8549052 | P23: =IF($Q16=MIN($Q15:$Q19),P21,P16) -> 4.775954 | Q23: =SUMPRODUCT($B$30:$E$30,M23:P23)+$F$30 -> 134.1559
B24: 5 | C24: 3 | D24: 2 | E24: 3 | F24: ='Лабораторная работа 2'!P42+'Лабораторная работа 2'!$F$21 -> 84.84 | M24: =IF($Q17=MIN($Q15:$Q19),M21,M17) -> 3 | N24: =IF($Q17=MIN($Q15:$Q19),N21,N17) -> 3.57735 | O24: =IF($Q17=MIN($Q15:$Q19),O21,O17) -> 2.7958758 | P24: =IF($Q17=MIN($Q15:$Q19),P21,P17) -> 2.8418861 | Q24: =SUMPRODUCT($B$30:$E$30,M24:P24)+$F$30 -> 82.283678
B25: 5 | C25: 4 | D25: 3 | E25: 4 | F25: ='Лабораторная работа 2'!P43+'Лабораторная работа 2'!$F$21 -> 110 | M25: =IF($Q18=MIN($Q15:$Q19),M21,M18) -> 3 | N25: =IF($Q18=MIN($Q15:$Q19),N21,N18) -> 3 | O25: =IF($Q18=MIN($Q15:$Q19),O21,O18) -> 3.61237 | P25: =IF($Q18=MIN($Q15:$Q19),P21,P18) -> 2.8418861 | Q25: =SUMPRODUCT($B$30:$E$30,M25:P25)+$F$30 -> 84.441762
B26: 5 | C26: 1 | D26: 4 | E26: 1 | F26: ='Лабораторная работа 2'!P44+'Лабораторная работа 2'!$F$21 -> 54.2 | M26: =IF($Q19=MIN($Q15:$Q19),M21,M19) -> 3 | N26: =IF($Q19=MIN($Q15:$Q19),N21,N19) -> 3 | O26: =IF($Q19=MIN($Q15:$Q19),O21,O19) -> 3 | P26: =IF($Q19=MIN($Q15:$Q19),P21,P19) -> 3.63246 | Q26: =SUMPRODUCT($B$30:$E$30,M26:P26)+$F$30 -> 94.884469
B27: 5 | C27: 5 | D27: 5 | E27: 5 | F27: ='Лабораторная работа 2'!P45+'Лабораторная работа 2'!$F$21 -> 140.08 | L27: Новая вершина | M27: =IF($Q22=MIN($Q22:$Q26),-M22,M22)+IF($Q23=MIN($Q22:$Q26),-M23,M23)+IF($Q24=MIN($Q22:$Q26),-M24,M24)+IF($Q25=MIN($Q22:$Q26), -M25,M25)+IF($Q26=MIN($Q22:$Q26),-M26,M26) -> 12.50462 | N27: =IF($Q22=MIN($Q22:$Q26),-N22,N22)+IF($Q23=MIN($Q22:$Q26),-N23,N23)+IF($Q24=MIN($Q22:$Q26),-N24,N24)+IF($Q25=MIN($Q22:$Q26), -N25,N25)+IF($Q26=MIN($Q22:$Q26),-N26,N26) -> 12.211325 | O27: =IF($Q22=MIN($Q22:$Q26),-O22,O22)+IF($Q23=MIN($Q22:$Q26),-O23,O23)+IF($Q24=MIN($Q22:$Q26),-O24,O24)+IF($Q25=MIN($Q22:$Q26), -O25,O25)+IF($Q26=MIN($Q22:$Q26),-O26,O26) -> 13.375522 | P27: =IF($Q22=MIN($Q22:$Q26),-P22,P22)+IF($Q23=MIN($Q22:$Q26),-P23,P23)+IF($Q24=MIN($Q22:$Q26),-P24,P24)+IF($Q25=MIN($Q22:$Q26), -P25,P25)+IF($Q26=MIN($Q22:$Q26),-P26,P26) -> 13.06653 | Q27: =MAX(M27:P27) -> 13.375522 | R27: =Q27/5 -> 2.6751045
L28: Новая пересчитанная вершина | M28: =M27/$R27 -> 4.6744419 | N28: =N27/$R27 -> 4.564803 | O28: =O27/$R27 -> 5 | P28: =P27/$R27 -> 4.8844934
B29: a1 | C29: a2 | D29: a3 | E29: a4 | F29: a0 | L29: 4 | M29: =IF($Q22=MIN($Q22:$Q26),M28,M22) -> 5 | N29: =IF($Q22=MIN($Q22:$Q26),N28,N22) -> 4.788675 | O29: =IF($Q22=MIN($Q22:$Q26),O28,O22) -> 4.7041229 | P29: =IF($Q22=MIN($Q22:$Q26),P28,P22) -> 4.6581161 | Q29: =SUMPRODUCT($B$30:$E$30,M29:P29)+$F$30 -> 132.12495 | R29: =MAX(Q29:Q33)-MIN(Q29:Q33) -> 51.352907
B30: ='Лабораторная работа 2'!B21 -> 2.82 | C30: ='Лабораторная работа 2'!C21 -> 3.22 | D30: ='Лабораторная работа 2'!D21 -> 4.92 | E30: ='Лабораторная работа 2'!E21 -> 17.02 | F30: ='Лабораторная работа 2'!F21 -> 0.18 | M30: =IF($Q23=MIN($Q22:$Q26),M28,M23) -> 4.5046204 | N30: =IF($Q23=MIN($Q22:$Q26),N28,N23) -> 5 | O30: =IF($Q23=MIN($Q22:$Q26),O28,O23) -> 4.8549052 | P30: =IF($Q23=MIN($Q22:$Q26),P28,P23) -> 4.775954 | Q30: =SUMPRODUCT($B$30:$E$30,M30:P30)+$F$30 -> 134.1559
B31: Уравнение регрессии | M31: =IF($Q24=MIN($Q22:$Q26),M28,M24) -> 4.6744419 | N31: =IF($Q24=MIN($Q22:$Q26),N28,N24) -> 4.564803 | O31: =IF($Q24=MIN($Q22:$Q26),O28,O24) -> 5 | P31: =IF($Q24=MIN($Q22:$Q26),P28,P24) -> 4.8844934 | Q31: =SUMPRODUCT($B$30:$E$30,M31:P31)+$F$30 -> 135.79467
B32: Y = 2,82X1 + 3,22X2 + 4,92X3 + 17,02X4 + 0,18 | M32: =IF($Q25=MIN($Q22:$Q26),M28,M25) -> 3 | N32: =IF($Q25=MIN($Q22:$Q26),N28,N25) -> 3 | O32: =IF($Q25=MIN($Q22:$Q26),O28,O25) -> 3.61237 | P32: =IF($Q25=MIN($Q22:$Q26),P28,P25) -> 2.8418861 | Q32: =SUMPRODUCT($B$30:$E$30,M32:P32)+$F$30 -> 84.441762
M33: =IF($Q26=MIN($Q22:$Q26),M28,M26) -> 3 | N33: =IF($Q26=MIN($Q22:$Q26),N28,N26) -> 3 | O33: =IF($Q26=MIN($Q22:$Q26),O28,O26) -> 3 | P33: =IF($Q26=MIN($Q22:$Q26),P28,P26) -> 3.63246 | Q33: =SUMPRODUCT($B$30:$E$30,M33:P33)+$F$30 -> 94.884469
L34: Новая вершина | M34: =IF($Q29=MIN($Q29:$Q33),-M29,M29)+IF($Q30=MIN($Q29:$Q33),-M30,M30)+IF($Q31=MIN($Q29:$Q33),-M31,M31)+IF($Q32=MIN($Q29:$Q33), -M32,M32)+IF($Q33=MIN($Q29:$Q33),-M33,M33) -> 14.179062 | N34: =IF($Q29=MIN($Q29:$Q33),-N29,N29)+IF($Q30=MIN($Q29:$Q33),-N30,N30)+IF($Q31=MIN($Q29:$Q33),-N31,N31)+IF($Q32=MIN($Q29:$Q33), -N32,N32)+IF($Q33=MIN($Q29:$Q33),-N33,N33) -> 14.353478 | O34: =IF($Q29=MIN($Q29:$Q33),-O29,O29)+IF($Q30=MIN($Q29:$Q33),-O30,O30)+IF($Q31=MIN($Q29:$Q33),-O31,O31)+IF($Q32=MIN($Q29:$Q33), -O32,O32)+IF($Q33=MIN($Q29:$Q33),-O33,O33) -> 13.946658 | P34: =IF($Q29=MIN($Q29:$Q33),-P29,P29)+IF($Q30=MIN($Q29:$Q33),-P30,P30)+IF($Q31=MIN($Q29:$Q33),-P31,P31)+IF($Q32=MIN($Q29:$Q33), -P32,P32)+IF($Q33=MIN($Q29:$Q33),-P33,P33) -> 15.109137 | Q34: =MAX(M34:P34) -> 15.109137 | R34: =Q34/5 -> 3.0218275
L35: Новая пересчитанная вершина | M35: =M34/$R34 -> 4.6922144 | N35: =N34/$R34 -> 4.749933 | O35: =O34/$R34 -> 4.6153059 | P35: =P34/$R34 -> 5
L36: 5 | M36: =IF($Q29=MIN($Q29:$Q33),M35,M29) -> 5 | N36: =IF($Q29=MIN($Q29:$Q33),N35,N29) -> 4.788675 | O36: =IF($Q29=MIN($Q29:$Q33),O35,O29) -> 4.7041229 | P36: =IF($Q29=MIN($Q29:$Q33),P35,P29) -> 4.6581161 | Q36: =SUMPRODUCT($B$30:$E$30,M36:P36)+$F$30 -> 132.12495 | R36: =MAX(Q36:Q40)-MIN(Q36:Q40) -> 41.629665
M37: =IF($Q30=MIN($Q29:$Q33),M35,M30) -> 4.5046204 | N37: =IF($Q30=MIN($Q29:$Q33),N35,N30) -> 5 | O37: =IF($Q30=MIN($Q29:$Q33),O35,O30) -> 4.8549052 | P37: =IF($Q30=MIN($Q29:$Q33),P35,P30) -> 4.775954 | Q37: =SUMPRODUCT($B$30:$E$30,M37:P37)+$F$30 -> 134.1559
M38: =IF($Q31=MIN($Q29:$Q33),M35,M31) -> 4.6744419 | N38: =IF($Q31=MIN($Q29:$Q33),N35,N31) -> 4.564803 | O38: =IF($Q31=MIN($Q29:$Q33),O35,O31) -> 5 | P38: =IF($Q31=MIN($Q29:$Q33),P35,P31) -> 4.8844934 | Q38: =SUMPRODUCT($B$30:$E$30,M38:P38)+$F$30 -> 135.79467
M39: =IF($Q32=MIN($Q29:$Q33),M35,M32) -> 4.6922144 | N39: =IF($Q32=MIN($Q29:$Q33),N35,N32) -> 4.749933 | O39: =IF($Q32=MIN($Q29:$Q33),O35,O32) -> 4.6153059 | P39: =IF($Q32=MIN($Q29:$Q33),P35,P32) -> 5 | Q39: =SUMPRODUCT($B$30:$E$30,M39:P39)+$F$30 -> 136.51413
M40: =IF($Q33=MIN($Q29:$Q33),M35,M33) -> 3 | N40: =IF($Q33=MIN($Q29:$Q33),N35,N33) -> 3 | O40: =IF($Q33=MIN($Q29:$Q33),O35,O33) -> 3 | P40: =IF($Q33=MIN($Q29:$Q33),P35,P33) -> 3.63246 | Q40: =SUMPRODUCT($B$30:$E$30,M40:P40)+$F$30 -> 94.884469
L41: Новая вершина | M41: =IF($Q36=MIN($Q36:$Q40),-M36,M36)+IF($Q37=MIN($Q36:$Q40),-M37,M37)+IF($Q38=MIN($Q36:$Q40),-M38,M38)+IF($Q39=MIN($Q36:$Q40), -M39,M39)+IF($Q40=MIN($Q36:$Q40),-M40,M40) -> 15.871277 | N41: =IF($Q36=MIN($Q36:$Q40),-N36,N36)+IF($Q37=MIN($Q36:$Q40),-N37,N37)+IF($Q38=MIN($Q36:$Q40),-N38,N38)+IF($Q39=MIN($Q36:$Q40), -N39,N39)+IF($Q40=MIN($Q36:$Q40),-N40,N40) -> 16.103411 | O41: =IF($Q36=MIN($Q36:$Q40),-O36,O36)+IF($Q37=MIN($Q36:$Q40),-O37,O37)+IF($Q38=MIN($Q36:$Q40),-O38,O38)+IF($Q39=MIN($Q36:$Q40), -O39,O39)+IF($Q40=MIN($Q36:$Q40),-O40,O40) -> 16.174334 | P41: =IF($Q36=MIN($Q36:$Q40),-P36,P36)+IF($Q37=MIN($Q36:$Q40),-P37,P37)+IF($Q38=MIN($Q36:$Q40),-P38,P38)+IF($Q39=MIN($Q36:$Q40), -P39,P39)+IF($Q40=MIN($Q36:$Q40),-P40,P40) -> 15.686103 | Q41: =MAX(M41:P41) -> 16.174334 | R41: =Q41/5 -> 3.2348668
...
